Traceback (most recent call last):
  File "/mnt/beegfs/lcesarini/2025_p_irio/src/./clip/clip_events_bilanci.py", line 138, in <module>
    all_ul=gpd.read_file(f"out/bilanci/{NR}_{year}/Event_{id}_IT_{NR}_{year}_{type_flood}.gpkg",layer="WD")
           ^^^^^^^^^^^^^^^^^^^^^^^^^^^^^^^^^^^^^^^^^^^^^^^^^^^^^^^^^^^^^^^^^^^^^^^^^^^^^^^^^^^^^^^^^^^^^^^^
  File "/home/luigi.cesarini/.conda/envs/geo/lib/python3.12/site-packages/geopandas/io/file.py", line 294, in _read_file
    return _read_file_pyogrio(
           ^^^^^^^^^^^^^^^^^^^
  File "/home/luigi.cesarini/.conda/envs/geo/lib/python3.12/site-packages/geopandas/io/file.py", line 547, in _read_file_pyogrio
    return pyogrio.read_dataframe(path_or_bytes, bbox=bbox, **kwargs)
           ^^^^^^^^^^^^^^^^^^^^^^^^^^^^^^^^^^^^^^^^^^^^^^^^^^^^^^^^^^
  File "/home/luigi.cesarini/.conda/envs/geo/lib/python3.12/site-packages/pyogrio/geopandas.py", line 265, in read_dataframe
    result = read_func(
             ^^^^^^^^^^
  File "/home/luigi.cesarini/.conda/envs/geo/lib/python3.12/site-packages/pyogrio/raw.py", line 198, in read
    return ogr_read(
           ^^^^^^^^^
  File "pyogrio/_io.pyx", line 1240, in pyogrio._io.ogr_read
  File "pyogrio/_io.pyx", line 220, in pyogrio._io.ogr_open
pyogrio.errors.DataSourceError: out/bilanci/Toscana_2017/Event_40863_IT_Toscana_2017_River.gpkg: No such file or directory
srun: error: cn07: task 0: Exited with exit code 1
